<?xml version="1.0" ?>

<robot  name="KneedCompassGait">
    <link name="base_link"/>
    <joint name="base" type="fixed">
        <child link="hip"/>
        <parent link="base_link"/>
    </joint>
<!--    <link name="mass">-->
<!--        <inertial>-->
<!--            <mass value="2"/>-->
<!--            <inertia ixx="0" ixy="0" ixz="0" iyy="0" iyz="0" izz="0"/>-->
<!--        </inertial>-->
<!--        <visual>-->
<!--            <geometry>-->
<!--                <sphere radius="0.05"/>-->
<!--            </geometry>-->
<!--            <material name="green">-->
<!--                <color rgba="0 1 0 1"/>-->
<!--            </material>-->
<!--        </visual>-->
<!--    </link>-->
<!--    <joint name="masstest" type="fixed">-->
<!--        <child link="mass"/>-->
<!--        <parent link="hip" />-->
<!--        <origin xyz="0 0.1 0"/>-->
<!--    </joint>-->
    <link name="hip">
        <inertial>
            <mass value="10"/>
            <inertia ixx="0" ixy="0" ixz="0" iyy="0" iyz="0" izz="0"/>
        </inertial>
        <visual>
            <geometry>
                <sphere radius="0.05"/>
            </geometry>
            <material name="green">
                <color rgba="0 1 0 1"/>
            </material>
        </visual>
    </link>
    <link name="hip2pin"/>
    <link name="pin2yaw"/>
    <link name="left_upper_leg">
        <visual>
            <origin xyz="0 0 -0.25"/>
            <geometry>
                <cylinder length="0.5" radius="0.0075"/>
            </geometry>
            <material name="red">
                <color rgba="1 0 0 1"/>
            </material>
        </visual>
    </link>
    <link name="left_upper_leg_mass">
        <visual>
            <origin xyz="0 0 -0.25"/>
            <geometry>
                <sphere radius="0.025"/>
            </geometry>
            <material name="red">
                <color rgba="1 0 0 1"/>
            </material>
        </visual>
        <inertial>
            <origin xyz="0 0 -0.25"/>
            <mass value="2.5"/>
            <inertia ixx="0" ixy="0" ixz="0" iyy="0" iyz="0" izz="0"/>
        </inertial>
    </link>
    <joint name="left_upper_leg_mass_weld" type="fixed">
        <parent link="left_upper_leg"/>
        <child link="left_upper_leg_mass"/>
    </joint>
    <link name="left_lower_leg">
        <visual>
            <origin xyz="0 0 -0.25"/>
            <geometry>
                <cylinder length="0.5" radius="0.0075"/>
            </geometry>
            <material name="red">
                <color rgba="1 0 0 1"/>
            </material>
        </visual>
        <visual>
            <origin xyz="0 0 -0.5" />
            <geometry>
                <sphere radius="0.01"/>
            </geometry>
            <material name="red">
                <color rgba="1 0 0 1"/>
            </material>
        </visual>
        <collision>
            <origin xyz="0 0 -0.5"/>
            <geometry>
                <sphere radius="0"/>
            </geometry>
        </collision>
<!--        <visual>-->
<!--            <origin xyz="-0.01 0 -0.5" />-->
<!--            <geometry>-->
<!--                <sphere radius="0.01"/>-->
<!--            </geometry>-->
<!--            <material name="red">-->
<!--                <color rgba="1 0 0 1"/>-->
<!--            </material>-->
<!--        </visual>-->
<!--        <collision>-->
<!--            <origin xyz="-0.01 0 -0.5"/>-->
<!--            <geometry>-->
<!--                <sphere radius="0"/>-->
<!--            </geometry>-->
<!--        </collision>-->
    </link>
    <link name="left_lower_leg_mass">
        <visual>
            <origin xyz="0 0 -0.25"/>
            <geometry>
                <sphere radius="0.025"/>
            </geometry>
            <material name="red">
                <color rgba="1 0 0 1"/>
            </material>
        </visual>
        <inertial>
            <origin xyz="0 0 -0.25"/>
            <mass value="2.5"/>
            <inertia ixx="0" ixy="0" ixz="0" iyy="0" iyz="0" izz="0"/>
        </inertial>
    </link>
    <joint name="left_lower_leg_mass_weld" type="fixed">
        <parent link="left_lower_leg"/>
        <child link="left_lower_leg_mass"/>
    </joint>
    <link name="right_upper_leg">
        <visual>
            <origin xyz="0 0 -0.25"/>
            <geometry>
                <cylinder length="0.5" radius="0.0075"/>
            </geometry>
            <material name="blue">
                <color rgba="0 0 1 1"/>
            </material>
        </visual>
    </link>
    <link name="right_upper_leg_mass">
        <visual>
            <origin xyz="0 0 -0.25"/>
            <geometry>
                <sphere radius="0.025"/>
            </geometry>
            <material name="blue">
                <color rgba="0 0 1 1"/>
            </material>
        </visual>
        <inertial>
            <origin xyz="0 0 -0.25"/>
            <mass value="2.5"/>
            <inertia ixx="0" ixy="0" ixz="0" iyy="0" iyz="0" izz="0"/>
        </inertial>
    </link>
    <joint name="right_upper_leg_mass_weld" type="fixed">
        <parent link="right_upper_leg"/>
        <child link="right_upper_leg_mass"/>
    </joint>
    <link name="right_lower_leg">
        <visual>
            <origin xyz="0 0 -0.25"/>
            <geometry>
                <cylinder length="0.5" radius="0.0075"/>
            </geometry>
            <material name="blue">
                <color rgba="0 0 1 1"/>
            </material>
        </visual>
        <visual>
            <origin xyz="0 0 -0.5" />
            <geometry>
                <sphere radius="0.01"/>
            </geometry>
            <material name="blue">
                <color rgba="0 0 1 1"/>
            </material>
        </visual>
        <collision>
            <origin xyz="0 0 -0.5"/>
            <geometry>
                <sphere radius="0"/>
            </geometry>
        </collision>
<!--        <visual>-->
<!--            <origin xyz="-0.01 0 -0.5" />-->
<!--            <geometry>-->
<!--                <sphere radius="0.01"/>-->
<!--            </geometry>-->
<!--            <material name="blue">-->
<!--                <color rgba="0 0 1 1"/>-->
<!--            </material>-->
<!--        </visual>-->
<!--        <collision>-->
<!--            <origin xyz="-0.01 0 -0.5"/>-->
<!--            <geometry>-->
<!--                <sphere radius="0"/>-->
<!--            </geometry>-->
<!--        </collision>-->
    </link>
    <link name="right_lower_leg_mass">
        <visual>
            <origin xyz="0 0 -0.25"/>
            <geometry>
                <sphere radius="0.025"/>
            </geometry>
            <material name="blue">
                <color rgba="0 0 1 1"/>
            </material>
        </visual>
        <inertial>
            <origin xyz="0 0 -0.25"/>
            <mass value="2.5"/>
            <inertia ixx="0" ixy="0" ixz="0" iyy="0" iyz="0" izz="0"/>
        </inertial>
    </link>
    <joint name="right_lower_leg_mass_weld" type="fixed">
        <parent link="right_lower_leg"/>
        <child link="right_lower_leg_mass"/>
    </joint>
    <joint name="left_leg_weld" type="fixed">
        <parent link="hip"/>
        <child link="left_upper_leg"/>
    </joint>
    <joint name="hip_roll" type="continuous">
        <parent link="hip"/>
        <child link="hip2pin"/>
        <axis xyz="1 0 0"/>
        <limit effort="200" velocity = "100"/>
    </joint>
    <joint name="hip_pin" type="continuous">
        <parent link="hip2pin"/>
        <child link="pin2yaw"/>
        <axis xyz="0 1 0"/>
        <limit effort="200" velocity="100"/>
    </joint>
    <joint name="left_knee_pin" type="revolute">
        <parent link="left_upper_leg"/>
        <child link="left_lower_leg"/>
        <axis xyz="0 1 0"/>
        <origin xyz="0 0 -0.5"/>
        <limit upper = "0" lower="-3.14" effort="200" velocity="100"/>
    </joint>
    <joint name="hip_yaw" type="continuous">
        <parent link="pin2yaw"/>
        <child link="right_upper_leg"/>
        <axis xyz="0 0 1"/>
        <limit effort="200" velocity="100"/>
    </joint>
    <joint name="right_knee_pin" type="revolute">
        <parent link="right_upper_leg"/>
        <child link="right_lower_leg"/>
        <axis xyz="0 1 0"/>
        <origin xyz="0 0 -0.5"/>
        <limit upper="0" lower="-3.14" effort="200" velocity="100"/>
    </joint>
    <transmission name="hip_1trans" type="SimpleTransmission">
        <actuator name="hip_roll_torque"/>
        <joint name="hip_roll"/>
        <mechanicalReduction>1</mechanicalReduction>
    </transmission>
    <transmission name="hip_2trans" type="SimpleTransmission">
        <actuator name="hip_pin_torque"/>
        <joint name="hip_pin"/>
        <mechanicalReduction>1</mechanicalReduction>
    </transmission>
    <transmission name="left_knee_trans" type="SimpleTransmission">
        <actuator name="left_knee_torque"/>
        <joint name="left_knee_pin"/>
        <mechanicalReduction>1</mechanicalReduction>
    </transmission>
    <transmission name="hip_3trans" type="SimpleTransmission">
        <actuator name="hip_yaw_torque"/>
        <joint name="hip_yaw"/>
        <mechanicalReduction>1</mechanicalReduction>
    </transmission>
    <transmission name="right_knee_trans" type="SimpleTransmission">
        <actuator name="right_knee_torque"/>
        <joint name="right_knee_pin"/>
        <mechanicalReduction>1</mechanicalReduction>
    </transmission>
<!--    <collision_filter_group name="robot_links">-->
<!--        <member link="left_lower_leg_mass"/>-->
<!--        <member link="right_lower_leg_mass"/>-->
<!--        <member link="left_lower_leg"/>-->
<!--        <member link="right_lower_leg"/>-->
<!--        <member link="right_upper_leg"/>-->
<!--        <member link="left_upper_leg"/>-->
<!--        <member link="hip"/>-->
<!--        <ignored_collision_filter_group collision_filter_group="robot_links"/>-->
<!--    </collision_filter_group>-->
</robot>